<?xml version="1.0" ?>
<!-- =================================================================================== -->
<!-- |    This document was autogenerated by xacro from /home/jelavice/catkin_workspaces/smb_ws/src/smb_common/smb_description/urdf/smb_standalone.urdf.xacro | -->
<!-- |    EDITING THIS FILE BY HAND IS NOT RECOMMENDED                                 | -->
<!-- =================================================================================== -->
<robot name="smb">
  <!-- Materials -->
  <material name="black">
    <color rgba="0 0 0 1.0"/>
  </material>
  <material name="dark_grey">
    <color rgba="0 0 0 0.6078431372549019 1.0"/>
  </material>
  <material name="blue">
    <color rgba="0 0 0.7843137254901961 1.0"/>
  </material>
  <material name="green">
    <color rgba="0 0.7843137254901961 0 1.0"/>
  </material>
  <material name="grey">
    <color rgba="0.19607843137254902 0.19607843137254902 0.19607843137254902 1.0"/>
  </material>
  <material name="orange">
    <color rgba="1.0 0.4235294117647059 0.0392156862745098 1.0"/>
  </material>
  <material name="brown">
    <color rgba="0.8705882352941177 0.8117647058823529 0.7647058823529411 1.0"/>
  </material>
  <material name="red">
    <color rgba="0.7843137254901961 0 0 1.0"/>
  </material>
  <material name="white">
    <color rgba="1.0 1.0 1.0 1.0"/>
  </material>
  <!-- t265_origin_xyz is the offset to the parent link -->
  <!-- t265_origin_rpy is the fixed axis roll, pitch and yaw angle such that the resulting frame has
       the x axis pointing forward ("out of camera"),
       the y axis pointing left and the z axis pointing upward -->
  <!-- another frame "realsense_t265_odom_frame is created that is in line with the one documented here:
       https://www.intel.com/content/dam/support/us/en/documents/emerging-technologies/intel-realsense-technology/IntelRealSenseTrackingT265Datasheet.pdf -->
  <link name="base_link">
    <collision>
      <origin rpy="0 0 0" xyz="0 0 0"/>
      <geometry>
        <box size="0.605 0.41 0.197"/>
      </geometry>
    </collision>
    <visual>
      <origin rpy="0 0 0" xyz="0 0 0"/>
      <geometry>
        <box size="0.605 0.41 0.197"/>
      </geometry>
      <material name="base_material">
        <color rgba="0.8 0.0 0.1 1.0"/>
      </material>
    </visual>
  </link>
  <link name="top">
    <collision>
      <origin rpy="0 0 0" xyz="-0.07 0 0"/>
      <geometry>
        <!-- <box size="${topLength} ${topWidth} ${topHeight}"/> -->
        <mesh filename="package://smb_description/urdf/new_payload/meshes/SMB_step.dae"/>
      </geometry>
    </collision>
    <visual>
      <origin rpy="0 0 0" xyz="0 0 0"/>
      <geometry>
        <!-- <box size="${topLength} ${topWidth} ${topHeight}"/> -->
        <mesh filename="package://smb_description/urdf/new_payload/meshes/SMB_step.dae"/>
      </geometry>
    </visual>
  </link>
  <gazebo reference="top">
    <material>Gazebo/Grey</material>
  </gazebo>
  <gazebo reference="base_link">
    <material>Gazebo/Red</material>
  </gazebo>
  <joint name="top_to_base_link" type="fixed">
    <parent link="base_link"/>
    <child link="top"/>
    <!-- <origin xyz="${topXOffset/2.0} 0.0 ${chassisHeight/2.0 + topHeight/2.0}" rpy="0 0 0"/> -->
    <origin rpy="0 0 0" xyz="0.0 0.0 0.0985"/>
  </joint>
  <!-- Fixed joint to add dummy inertia link -->
  <joint name="base_to_base_inertia" type="fixed">
    <parent link="base_link"/>
    <child link="base_inertia"/>
    <origin rpy="0 0 0" xyz="0 0 0"/>
  </joint>
  <!-- Dummy inertia link, because KDL cannot have inertia on the base link -->
  <link name="base_inertia">
    <inertial>
      <origin rpy="0 0 0" xyz="0 0 0"/>
      <mass value="40"/>
      <inertia ixx="0.6896966666666665" ixy="0" ixz="0" iyy="1.3494466666666665" iyz="0" izz="1.3494466666666665"/>
    </inertial>
  </link>
  <joint name="LF_WHEEL_JOINT" type="continuous">
    <parent link="base_link"/>
    <child link="LF_WHEEL"/>
    <origin rpy="-1.5707963267948966 0 0" xyz="0.2159 0.285 -0.018500000000000003"/>
    <axis rpy="0 0 0" xyz="0 0 1"/>
    <dynamics damping="1.0" friction="0.0"/>
    <limit effort="100" velocity="10"/>
    <joint_properties damping="0.2" friction="0.2"/>
  </joint>
  <link name="LF_WHEEL">
    <collision>
      <origin rpy="0 0 0" xyz="0 0 0"/>
      <geometry>
        <cylinder length="0.01" radius="0.19"/>
      </geometry>
    </collision>
    <visual>
      <origin rpy="1.570796 0  0" xyz="0 0 0"/>
      <geometry>
        <mesh filename="package://smb_description/urdf/meshes/wheel.dae"/>
      </geometry>
    </visual>
    <inertial>
      <origin rpy="0 0 0" xyz="0 0 0"/>
      <mass value="5"/>
      <inertia ixx="0.04929166666666668" ixy="0" ixz="0" iyy="0.04929166666666668" iyz="0" izz="0.09025"/>
    </inertial>
  </link>
  <gazebo reference="LF_WHEEL">
    <mu1 value="0.5"/>
    <mu2 value="0.5"/>
    <fdir1 value="1 0 0"/>
    <kp>10000000.0</kp>
    <kd>1.0</kd>
    <minDepth>0.005</minDepth>
    <maxVel>100.0</maxVel>
    <material>Gazebo/DarkGrey</material>
  </gazebo>
  <transmission name="LF_WHEEL_TRANS">
    <type>transmission_interface/SimpleTransmission</type>
    <joint name="LF_WHEEL_JOINT">
      <hardwareInterface>hardware_interface/VelocityJointInterface</hardwareInterface>
      <hardwareInterface>hardware_interface/EffortJointInterface</hardwareInterface>
      <hardwareInterface>hardware_interface/PositionJointInterface</hardwareInterface>
    </joint>
    <actuator name="LF_WHEEL_ACTUATOR">
      <hardwareInterface>hardware_interface/VelocityJointInterface</hardwareInterface>
      <hardwareInterface>hardware_interface/EffortJointInterface</hardwareInterface>
      <hardwareInterface>hardware_interface/PositionJointInterface</hardwareInterface>
      <mechanicalReduction>1</mechanicalReduction>
    </actuator>
  </transmission>
  <joint name="RF_WHEEL_JOINT" type="continuous">
    <parent link="base_link"/>
    <child link="RF_WHEEL"/>
    <origin rpy="-1.5707963267948966 0 0" xyz="0.2159 -0.285 -0.018500000000000003"/>
    <axis rpy="0 0 0" xyz="0 0 1"/>
    <dynamics damping="1.0" friction="0.0"/>
    <limit effort="100" velocity="10"/>
    <joint_properties damping="0.2" friction="0.2"/>
  </joint>
  <link name="RF_WHEEL">
    <collision>
      <origin rpy="0 0 0" xyz="0 0 0"/>
      <geometry>
        <cylinder length="0.01" radius="0.19"/>
      </geometry>
    </collision>
    <visual>
      <origin rpy="1.570796 0  0" xyz="0 0 0"/>
      <geometry>
        <mesh filename="package://smb_description/urdf/meshes/wheel.dae"/>
      </geometry>
    </visual>
    <inertial>
      <origin rpy="0 0 0" xyz="0 0 0"/>
      <mass value="5"/>
      <inertia ixx="0.04929166666666668" ixy="0" ixz="0" iyy="0.04929166666666668" iyz="0" izz="0.09025"/>
    </inertial>
  </link>
  <gazebo reference="RF_WHEEL">
    <mu1 value="0.5"/>
    <mu2 value="0.5"/>
    <fdir1 value="1 0 0"/>
    <kp>10000000.0</kp>
    <kd>1.0</kd>
    <minDepth>0.005</minDepth>
    <maxVel>100.0</maxVel>
    <material>Gazebo/DarkGrey</material>
  </gazebo>
  <transmission name="RF_WHEEL_TRANS">
    <type>transmission_interface/SimpleTransmission</type>
    <joint name="RF_WHEEL_JOINT">
      <hardwareInterface>hardware_interface/VelocityJointInterface</hardwareInterface>
      <hardwareInterface>hardware_interface/EffortJointInterface</hardwareInterface>
      <hardwareInterface>hardware_interface/PositionJointInterface</hardwareInterface>
    </joint>
    <actuator name="RF_WHEEL_ACTUATOR">
      <hardwareInterface>hardware_interface/VelocityJointInterface</hardwareInterface>
      <hardwareInterface>hardware_interface/EffortJointInterface</hardwareInterface>
      <hardwareInterface>hardware_interface/PositionJointInterface</hardwareInterface>
      <mechanicalReduction>1</mechanicalReduction>
    </actuator>
  </transmission>
  <joint name="LH_WHEEL_JOINT" type="continuous">
    <parent link="base_link"/>
    <child link="LH_WHEEL"/>
    <origin rpy="-1.5707963267948966 0 0" xyz="-0.2159 0.285 -0.018500000000000003"/>
    <axis rpy="0 0 0" xyz="0 0 1"/>
    <dynamics damping="1.0" friction="0.0"/>
    <limit effort="100" velocity="10"/>
    <joint_properties damping="0.2" friction="0.2"/>
  </joint>
  <link name="LH_WHEEL">
    <collision>
      <origin rpy="0 0 0" xyz="0 0 0"/>
      <geometry>
        <cylinder length="0.01" radius="0.19"/>
      </geometry>
    </collision>
    <visual>
      <origin rpy="1.570796 0  0" xyz="0 0 0"/>
      <geometry>
        <mesh filename="package://smb_description/urdf/meshes/wheel.dae"/>
      </geometry>
    </visual>
    <inertial>
      <origin rpy="0 0 0" xyz="0 0 0"/>
      <mass value="5"/>
      <inertia ixx="0.04929166666666668" ixy="0" ixz="0" iyy="0.04929166666666668" iyz="0" izz="0.09025"/>
    </inertial>
  </link>
  <gazebo reference="LH_WHEEL">
    <mu1 value="0.0"/>
    <mu2 value="0.0"/>
    <fdir1 value="1 0 0"/>
    <kp>10000000.0</kp>
    <kd>1.0</kd>
    <minDepth>0.005</minDepth>
    <maxVel>100.0</maxVel>
    <material>Gazebo/DarkGrey</material>
  </gazebo>
  <transmission name="LH_WHEEL_TRANS">
    <type>transmission_interface/SimpleTransmission</type>
    <joint name="LH_WHEEL_JOINT">
      <hardwareInterface>hardware_interface/VelocityJointInterface</hardwareInterface>
      <hardwareInterface>hardware_interface/EffortJointInterface</hardwareInterface>
      <hardwareInterface>hardware_interface/PositionJointInterface</hardwareInterface>
    </joint>
    <actuator name="LH_WHEEL_ACTUATOR">
      <hardwareInterface>hardware_interface/VelocityJointInterface</hardwareInterface>
      <hardwareInterface>hardware_interface/EffortJointInterface</hardwareInterface>
      <hardwareInterface>hardware_interface/PositionJointInterface</hardwareInterface>
      <mechanicalReduction>1</mechanicalReduction>
    </actuator>
  </transmission>
  <joint name="RH_WHEEL_JOINT" type="continuous">
    <parent link="base_link"/>
    <child link="RH_WHEEL"/>
    <origin rpy="-1.5707963267948966 0 0" xyz="-0.2159 -0.285 -0.018500000000000003"/>
    <axis rpy="0 0 0" xyz="0 0 1"/>
    <dynamics damping="1.0" friction="0.0"/>
    <limit effort="100" velocity="10"/>
    <joint_properties damping="0.2" friction="0.2"/>
  </joint>
  <link name="RH_WHEEL">
    <collision>
      <origin rpy="0 0 0" xyz="0 0 0"/>
      <geometry>
        <cylinder length="0.01" radius="0.19"/>
      </geometry>
    </collision>
    <visual>
      <origin rpy="1.570796 0  0" xyz="0 0 0"/>
      <geometry>
        <mesh filename="package://smb_description/urdf/meshes/wheel.dae"/>
      </geometry>
    </visual>
    <inertial>
      <origin rpy="0 0 0" xyz="0 0 0"/>
      <mass value="5"/>
      <inertia ixx="0.04929166666666668" ixy="0" ixz="0" iyy="0.04929166666666668" iyz="0" izz="0.09025"/>
    </inertial>
  </link>
  <gazebo reference="RH_WHEEL">
    <mu1 value="0.2"/>
    <mu2 value="0.2"/>
    <fdir1 value="1 0 0"/>
    <kp>10000000.0</kp>
    <kd>1.0</kd>
    <minDepth>0.005</minDepth>
    <maxVel>100.0</maxVel>
    <material>Gazebo/DarkGrey</material>
  </gazebo>
  <transmission name="RH_WHEEL_TRANS">
    <type>transmission_interface/SimpleTransmission</type>
    <joint name="RH_WHEEL_JOINT">
      <hardwareInterface>hardware_interface/VelocityJointInterface</hardwareInterface>
      <hardwareInterface>hardware_interface/EffortJointInterface</hardwareInterface>
      <hardwareInterface>hardware_interface/PositionJointInterface</hardwareInterface>
    </joint>
    <actuator name="RH_WHEEL_ACTUATOR">
      <hardwareInterface>hardware_interface/VelocityJointInterface</hardwareInterface>
      <hardwareInterface>hardware_interface/EffortJointInterface</hardwareInterface>
      <hardwareInterface>hardware_interface/PositionJointInterface</hardwareInterface>
      <mechanicalReduction>1</mechanicalReduction>
    </actuator>
  </transmission>
  <gazebo>
    <plugin filename="libhector_gazebo_ros_imu.so" name="smb_imu_plugin">
      <updateRate>400</updateRate>
      <bodyName>imu_link</bodyName>
      <frameId>imu_link</frameId>
      <topicName>/imu0</topicName>
      <serviceName>/imu/calibrate</serviceName>
      <accelOffset>0.0 0.0 0.0</accelOffset>
      <accelDrift>0.0 0.0 0.0</accelDrift>
      <accelDriftFrequency>0.0 0.0 0.0</accelDriftFrequency>
      <accelGaussianNoise>0.0 0.0 0.0</accelGaussianNoise>
      <rateOffset>0.0 0.0 0.0</rateOffset>
      <rateDrift>0.0 0.0 0.0</rateDrift>
      <rateDriftFrequency>0.0 0.0 0.0</rateDriftFrequency>
      <rateGaussianNoise>0.0 0.0 0.0</rateGaussianNoise>
      <headingOffset>0.0</headingOffset>
      <headingDrift>0.0</headingDrift>
      <headingDriftFrequency>0.0</headingDriftFrequency>
      <headingGaussianNoise>0.0</headingGaussianNoise>
    </plugin>
  </gazebo>
  <!-- Imu is fixed to the base link -->
  <joint name="imu_joint" type="fixed">
    <origin rpy="0 0 0" xyz="0.2554 -0.02397 0.1795"/>
    <parent link="base_link"/>
    <child link="imu_link"/>
  </joint>
  <!-- Imu link -->
  <link name="imu_link">
    <inertial>
      <mass value="0.001"/>
      <origin rpy="0 0 0" xyz="0 0 0"/>
      <inertia ixx="0.0001" ixy="0" ixz="0" iyy="0.000001" iyz="0" izz="0.0001"/>
    </inertial>
    <visual>
      <origin rpy="0 0 0" xyz="0 0 0"/>
      <geometry>
        <!-- <box size="0.04 0.05 0.02"/> -->
        <mesh filename="package://smb_description/urdf/new_payload/meshes/SMB_imu.dae"/>
      </geometry>
    </visual>
    <collision>
      <origin rpy="0 0 0" xyz="0 0 0"/>
      <geometry>
        <!-- <box size=".001 .001 .001"/> -->
        <mesh filename="package://smb_description/urdf/new_payload/meshes/SMB_imu.dae"/>
      </geometry>
    </collision>
    <material name="orange">
      <color rgba="255 108 10 255"/>
    </material>
  </link>
  <link name="imu">
    <inertial>
      <mass value="0.001"/>
      <origin rpy="0 0 0" xyz="0 0 0"/>
      <inertia ixx="0.0001" ixy="0" ixz="0" iyy="0.000001" iyz="0" izz="0.0001"/>
    </inertial>
  </link>
  <joint name="imu_imu_link_joint" type="fixed">
    <origin rpy="0 0 0" xyz="0 0 0"/>
    <parent link="imu_link"/>
    <child link="imu"/>
  </joint>
  <gazebo reference="imu_link">
    <material>Gazebo/Orange</material>
  </gazebo>
  <gazebo reference="imu_joint">
    <disableFixedJointLumping>true</disableFixedJointLumping>
  </gazebo>
  <!-- <xacro:GPS base_link="${base_link_name}" simulation="${simulation}"/> -->
  <link name="mono_link">
    <inertial>
      <mass value="0.01"/>
      <!-- [kg] -->
      <inertia ixx="1e-5" ixy="0" ixz="0" iyy="1e-5" iyz="0" izz="1e-5"/>
    </inertial>
    <visual>
      <geometry>
        <box size="0.02 0.05 0.03"/>
      </geometry>
    </visual>
    <collision>
      <geometry>
        <box size="0.02 0.05 0.03"/>
      </geometry>
    </collision>
    <material name="red">
      <color rgba="255 0 10 255"/>
    </material>
  </link>
  <gazebo reference="mono_link">
    <material>Gazebo/Red</material>
  </gazebo>
  <joint name="mono_camera_joint" type="fixed">
    <origin rpy="0 0 0" xyz="0.35 -0.15 0.29"/>
    <parent link="base_link"/>
    <child link="mono_link"/>
  </joint>
  <gazebo reference="mono_camera_joint">
    <disableFixedJointLumping>true</disableFixedJointLumping>
  </gazebo>
  <gazebo reference="mono_link">
    <sensor name="mono_cam" type="camera">
      <pose>0 0 0 0 0 0</pose>
      <visualize>false</visualize>
      <update_rate>30</update_rate>
      <camera>
        <horizontal_fov>1.3962634</horizontal_fov>
        <!-- 80 deg-->
         &gt;
          
        <image>
          <width>640</width>
          <height>480</height>
          <format>R8G8B8</format>
        </image>
        <clip>
          <near>0.01</near>
          <far>100</far>
        </clip>
        <noise>
          <type>gaussian</type>
          <!-- Noise parameters based on published spec for Hokuyo laser
                achieving "+-30mm" accuracy at range < 10m.  A mean of 0.0m and
                stddev of 0.01m will put 99.7% of samples within 0.03m of the true
                reading. -->
          <mean>0.0</mean>
          <stddev>0.007</stddev>
        </noise>
      </camera>
      <plugin filename="libgazebo_ros_camera.so" name="gazebo_ros_camera_controller">
        <alwaysOn>true</alwaysOn>
        <updateRate>0.0</updateRate>
        <cameraName>mono_cam</cameraName>
        <imageTopicName>/mono/cam0/image_raw</imageTopicName>
        <cameraInfoTopicName>camera_info</cameraInfoTopicName>
        <frameName>mono_link</frameName>
        <hackBaseline>0.07</hackBaseline>
        <distortionK1>0.0</distortionK1>
        <distortionK2>0.0</distortionK2>
        <distortionK3>0.0</distortionK3>
        <distortionT1>0.0</distortionT1>
        <distortionT2>0.0</distortionT2>
      </plugin>
    </sensor>
  </gazebo>
  <link name="blackfly0_link">
    <inertial>
      <mass value="0.01"/>
      <!-- [kg] -->
      <inertia ixx="1e-5" ixy="0" ixz="0" iyy="1e-5" iyz="0" izz="1e-5"/>
    </inertial>
    <visual>
      <geometry>
        <mesh filename="package://smb_description/urdf/new_payload/meshes/SMB_blackfly_camera.dae"/>
      </geometry>
    </visual>
    <collision>
      <geometry>
        <mesh filename="package://smb_description/urdf/new_payload/meshes/SMB_blackfly_camera.dae"/>
      </geometry>
    </collision>
    <material name="red">
      <color rgba="255 0 10 255"/>
    </material>
  </link>
  <gazebo reference="blackfly0_link">
    <material>Gazebo/Red</material>
  </gazebo>
  <joint name="blackfly0_camera_joint" type="fixed">
    <!-- <origin xyz="${blackfly_origin_xyz}" rpy="${blackfly_origin_rpy}"/> -->
    <origin rpy="0 0 0" xyz="0.29082 0.04458 0.194"/>
    <parent link="base_link"/>
    <child link="blackfly0_link"/>
  </joint>
  <gazebo reference="blackfly0_camera_joint">
    <disableFixedJointLumping>true</disableFixedJointLumping>
  </gazebo>
  <link name="blackfly0_optical_link"/>
  <joint name="blackfly0_camera_optical_joint" type="fixed">
    <origin rpy="-1.57 0 -1.57" xyz="0.0066 0 0"/>
    <parent link="blackfly0_link"/>
    <child link="blackfly0_optical_link"/>
  </joint>
  <gazebo reference="blackfly0_link">
    <sensor name="blackfly0_cam" type="camera">
      <pose>0.0066 0 0 0 0 0</pose>
      <visualize>false</visualize>
      <update_rate>30</update_rate>
      <camera>
        <horizontal_fov>1.3962634</horizontal_fov>
        <!-- 80 deg-->
         &gt;
          
        <image>
          <width>720</width>
          <height>540</height>
          <format>R8G8B8</format>
        </image>
        <clip>
          <near>0.01</near>
          <far>100</far>
        </clip>
        <noise>
          <type>gaussian</type>
          <!-- Noise parameters based on published spec for Hokuyo laser
                achieving "+-30mm" accuracy at range < 10m.  A mean of 0.0m and
                stddev of 0.01m will put 99.7% of samples within 0.03m of the true
                reading. -->
          <mean>0.0</mean>
          <stddev>0.007</stddev>
        </noise>
      </camera>
      <plugin filename="libgazebo_ros_camera.so" name="gazebo_ros_camera_controller">
        <alwaysOn>true</alwaysOn>
        <updateRate>0.0</updateRate>
        <cameraName>blackfly0_cam</cameraName>
        <imageTopicName>/blackfly0/color/image_raw</imageTopicName>
        <cameraInfoTopicName>/blackfly0/color/camera_info</cameraInfoTopicName>
        <frameName>blackfly0_optical_link</frameName>
        <hackBaseline>0.07</hackBaseline>
        <distortionK1>0.0</distortionK1>
        <distortionK2>0.0</distortionK2>
        <distortionK3>0.0</distortionK3>
        <distortionT1>0.0</distortionT1>
        <distortionT2>0.0</distortionT2>
      </plugin>
    </sensor>
  </gazebo>
  <link name="blackfly1_link">
    <inertial>
      <mass value="0.01"/>
      <!-- [kg] -->
      <inertia ixx="1e-5" ixy="0" ixz="0" iyy="1e-5" iyz="0" izz="1e-5"/>
    </inertial>
    <visual>
      <geometry>
        <mesh filename="package://smb_description/urdf/new_payload/meshes/SMB_blackfly_camera.dae"/>
      </geometry>
    </visual>
    <collision>
      <geometry>
        <mesh filename="package://smb_description/urdf/new_payload/meshes/SMB_blackfly_camera.dae"/>
      </geometry>
    </collision>
    <material name="red">
      <color rgba="255 0 10 255"/>
    </material>
  </link>
  <gazebo reference="blackfly1_link">
    <material>Gazebo/Red</material>
  </gazebo>
  <joint name="blackfly1_camera_joint" type="fixed">
    <!-- <origin xyz="${blackfly_origin_xyz}" rpy="${blackfly_origin_rpy}"/> -->
    <origin rpy="0 0 0" xyz="0.29082 -0.04542 0.194"/>
    <parent link="base_link"/>
    <child link="blackfly1_link"/>
  </joint>
  <gazebo reference="blackfly1_camera_joint">
    <disableFixedJointLumping>true</disableFixedJointLumping>
  </gazebo>
  <link name="blackfly1_optical_link"/>
  <joint name="blackfly1_camera_optical_joint" type="fixed">
    <origin rpy="-1.57 0 -1.57" xyz="0.0066 0 0"/>
    <parent link="blackfly1_link"/>
    <child link="blackfly1_optical_link"/>
  </joint>
  <gazebo reference="blackfly1_link">
    <sensor name="blackfly1_cam" type="camera">
      <pose>0.0066 0 0 0 0 0</pose>
      <visualize>false</visualize>
      <update_rate>30</update_rate>
      <camera>
        <horizontal_fov>1.3962634</horizontal_fov>
        <!-- 80 deg-->
         &gt;
          
        <image>
          <width>720</width>
          <height>540</height>
          <format>R8G8B8</format>
        </image>
        <clip>
          <near>0.01</near>
          <far>100</far>
        </clip>
        <noise>
          <type>gaussian</type>
          <!-- Noise parameters based on published spec for Hokuyo laser
                achieving "+-30mm" accuracy at range < 10m.  A mean of 0.0m and
                stddev of 0.01m will put 99.7% of samples within 0.03m of the true
                reading. -->
          <mean>0.0</mean>
          <stddev>0.007</stddev>
        </noise>
      </camera>
      <plugin filename="libgazebo_ros_camera.so" name="gazebo_ros_camera_controller">
        <alwaysOn>true</alwaysOn>
        <updateRate>0.0</updateRate>
        <cameraName>blackfly1_cam</cameraName>
        <imageTopicName>/blackfly1/color/image_raw</imageTopicName>
        <cameraInfoTopicName>/blackfly1/color/camera_info</cameraInfoTopicName>
        <frameName>blackfly1_optical_link</frameName>
        <hackBaseline>0.07</hackBaseline>
        <distortionK1>0.0</distortionK1>
        <distortionK2>0.0</distortionK2>
        <distortionK3>0.0</distortionK3>
        <distortionT1>0.0</distortionT1>
        <distortionT2>0.0</distortionT2>
      </plugin>
    </sensor>
  </gazebo>
  <link name="blackfly_left_link">
    <inertial>
      <mass value="0.01"/>
      <!-- [kg] -->
      <inertia ixx="1e-5" ixy="0" ixz="0" iyy="1e-5" iyz="0" izz="1e-5"/>
    </inertial>
    <visual>
      <geometry>
        <mesh filename="package://smb_description/urdf/new_payload/meshes/SMB_blackfly_camera.dae"/>
      </geometry>
    </visual>
    <collision>
      <geometry>
        <mesh filename="package://smb_description/urdf/new_payload/meshes/SMB_blackfly_camera.dae"/>
      </geometry>
    </collision>
    <material name="red">
      <color rgba="255 0 10 255"/>
    </material>
  </link>
  <gazebo reference="blackfly_left_link">
    <material>Gazebo/Red</material>
  </gazebo>
  <link name="blackfly_right_link">
    <inertial>
      <mass value="0.01"/>
      <!-- [kg] -->
      <inertia ixx="1e-5" ixy="0" ixz="0" iyy="1e-5" iyz="0" izz="1e-5"/>
    </inertial>
    <visual>
      <geometry>
        <mesh filename="package://smb_description/urdf/new_payload/meshes/SMB_blackfly_camera.dae"/>
      </geometry>
    </visual>
    <collision>
      <geometry>
        <mesh filename="package://smb_description/urdf/new_payload/meshes/SMB_blackfly_camera.dae"/>
      </geometry>
    </collision>
    <material name="red">
      <color rgba="255 0 10 255"/>
    </material>
  </link>
  <gazebo reference="blackfly_right_link">
    <material>Gazebo/Red</material>
  </gazebo>
  <joint name="blackfly_left_camera_joint" type="fixed">
    <origin rpy="0 0 0" xyz="0.29082 0.04458 0.194"/>
    <parent link="base_link"/>
    <child link="blackfly_left_link"/>
  </joint>
  <gazebo reference="blackfly_left_camera_joint">
    <disableFixedJointLumping>true</disableFixedJointLumping>
  </gazebo>
  <joint name="blackfly_right_camera_joint" type="fixed">
    <origin rpy="0 0 0" xyz="0.29082 -0.04542 0.194"/>
    <parent link="base_link"/>
    <child link="blackfly_right_link"/>
  </joint>
  <gazebo reference="blackfly_right_camera_joint">
    <disableFixedJointLumping>true</disableFixedJointLumping>
  </gazebo>
  <link name="blackfly_left_optical_link"/>
  <link name="blackfly_right_optical_link"/>
  <joint name="blackfly_left_camera_optical_joint" type="fixed">
    <origin rpy="-1.57 0 -1.57" xyz="0.0066 0 0"/>
    <parent link="blackfly_left_link"/>
    <child link="blackfly_left_optical_link"/>
  </joint>
  <joint name="blackfly_right_camera_optical_joint" type="fixed">
    <origin rpy="-1.57 0 -1.57" xyz="0.0066 0 0"/>
    <parent link="blackfly_right_link"/>
    <child link="blackfly_right_optical_link"/>
  </joint>
  <gazebo reference="blackfly_left_link">
    <sensor name="blackfly_stereo_cam" type="multicamera">
      <visualize>false</visualize>
      <update_rate>30</update_rate>
      <camera name="left">
        <pose>0.0066 0 0 0 0 0</pose>
        <horizontal_fov>1.3962634</horizontal_fov>
        <!-- 80 deg-->
         &gt;
          
        <image>
          <width>720</width>
          <height>540</height>
          <format>R8G8B8</format>
        </image>
        <clip>
          <near>0.01</near>
          <far>300</far>
        </clip>
        <noise>
          <type>gaussian</type>
          <!-- Noise parameters based on published spec for Hokuyo laser
                achieving "+-30mm" accuracy at range < 10m.  A mean of 0.0m and
                stddev of 0.01m will put 99.7% of samples within 0.03m of the true
                reading. -->
          <mean>0.0</mean>
          <stddev>0.007</stddev>
        </noise>
      </camera>
      <camera name="right">
        <pose>0.0066 -0.09 0 0 0 0</pose>
        <horizontal_fov>1.3962634</horizontal_fov>
        <!-- 80 deg-->
         &gt;
          
        <image>
          <width>720</width>
          <height>540</height>
          <format>R8G8B8</format>
        </image>
        <clip>
          <near>0.01</near>
          <far>300</far>
        </clip>
        <noise>
          <type>gaussian</type>
          <!-- Noise parameters based on published spec for Hokuyo laser
                achieving "+-30mm" accuracy at range < 10m.  A mean of 0.0m and
                stddev of 0.01m will put 99.7% of samples within 0.03m of the true
                reading. -->
          <mean>0.0</mean>
          <stddev>0.007</stddev>
        </noise>
      </camera>
      <plugin filename="libgazebo_ros_multicamera.so" name="stereo_camera_controller">
        <alwaysOn>true</alwaysOn>
        <updateRate>0.0</updateRate>
        <cameraName>blackfly_stereo_cam</cameraName>
        <imageTopicName>image_raw</imageTopicName>
        <cameraInfoTopicName>camera_info</cameraInfoTopicName>
        <frameName>blackfly_left_optical_link</frameName>
        <hackBaseline>0.09</hackBaseline>
        <distortionK1>0.0</distortionK1>
        <distortionK2>0.0</distortionK2>
        <distortionK3>0.0</distortionK3>
        <distortionT1>0.0</distortionT1>
        <distortionT2>0.0</distortionT2>
      </plugin>
    </sensor>
  </gazebo>
  <joint name="rslidar_base_mount_joint" type="fixed">
    <origin rpy="0 0 1.5707963267948966" xyz="0.00445 0 0.39649999999999996"/>
    <parent link="base_link"/>
    <child link="rslidar_base_link"/>
  </joint>
  <link name="rslidar_base_link">
    <inertial>
      <mass value="0.83"/>
      <origin xyz="0 0 0.03585"/>
      <inertia ixx="0.000908059425" ixy="0" ixz="0" iyy="0.000908059425" iyz="0" izz="0.0011049624"/>
    </inertial>
    <visual>
      <geometry>
        <mesh filename="package://velodyne_description/meshes/VLP16_base_1.dae"/>
      </geometry>
    </visual>
    <visual>
      <geometry>
        <mesh filename="package://velodyne_description/meshes/VLP16_base_2.dae"/>
      </geometry>
    </visual>
    <collision>
      <origin rpy="0 0 0" xyz="0 0 0.03585"/>
      <geometry>
        <cylinder length="0.0717" radius="0.0516"/>
      </geometry>
    </collision>
  </link>
  <joint name="rslidar_base_scan_joint" type="fixed">
    <origin rpy="0 0 0" xyz="0 0 0.0377"/>
    <parent link="rslidar_base_link"/>
    <child link="rslidar"/>
  </joint>
  <link name="rslidar">
    <inertial>
      <mass value="0.01"/>
      <origin xyz="0 0 0"/>
      <inertia ixx="1e-7" ixy="0" ixz="0" iyy="1e-7" iyz="0" izz="1e-7"/>
    </inertial>
    <visual>
      <origin xyz="0 0 -0.0377"/>
      <geometry>
        <mesh filename="package://velodyne_description/meshes/VLP16_scan.dae"/>
      </geometry>
    </visual>
  </link>
  <!-- Gazebo requires the velodyne_gazebo_plugins package -->
  <gazebo reference="rslidar">
    <sensor name="rslidar-VLP16" type="ray">
      <pose>0 0 0 0 0 0</pose>
      <visualize>false</visualize>
      <update_rate>10</update_rate>
      <ray>
        <scan>
          <horizontal>
            <samples>440</samples>
            <resolution>1</resolution>
            <min_angle>-3.141592653589793</min_angle>
            <max_angle>3.141592653589793</max_angle>
          </horizontal>
          <vertical>
            <samples>16</samples>
            <resolution>1</resolution>
            <min_angle>-0.2617993877991494</min_angle>
            <max_angle> 0.2617993877991494</max_angle>
          </vertical>
        </scan>
        <range>
          <min>0.3</min>
          <max>131.0</max>
          <resolution>0.001</resolution>
        </range>
        <noise>
          <type>gaussian</type>
          <mean>0.0</mean>
          <stddev>0.0</stddev>
        </noise>
      </ray>
      <plugin filename="libgazebo_ros_velodyne_laser.so" name="gazebo_ros_laser_controller">
        <topicName>/rslidar_points</topicName>
        <frameName>rslidar</frameName>
        <organize_cloud>False</organize_cloud>
        <min_range>0.9</min_range>
        <max_range>130.0</max_range>
        <gaussianNoise>0.008</gaussianNoise>
      </plugin>
    </sensor>
  </gazebo>
  <gazebo reference="rslidar_base_mount_joint">
    <preserveFixedJoint>true</preserveFixedJoint>
  </gazebo>
  <gazebo reference="rslidar_base_scan_joint">
    <preserveFixedJoint>true</preserveFixedJoint>
  </gazebo>
  <gazebo>
    <plugin filename="libodometry_source_plugin.so" name="smb_odometry_plugin">
      <robotNamespace>smb</robotNamespace>
      <bodyName>rslidar</bodyName>
      <topicName>/rslidar_ground_truth</topicName>
      <odomFrame>map</odomFrame>
      <childOdomFrame>lidar</childOdomFrame>
      <publishTf>False</publishTf>
      <xyzOffset>0 0 0</xyzOffset>
      <rpyOffset>0 0 0</rpyOffset>
      <gaussianNoise>0</gaussianNoise>
      <updateRate>20</updateRate>
      <maxLinearSpeedBeforeSettle>0.001</maxLinearSpeedBeforeSettle>
      <maxAngularSpeedBeforeSettle>0.001</maxAngularSpeedBeforeSettle>
    </plugin>
  </gazebo>
  <link name="lidar_mount_link">
    <visual>
      <geometry>
        <mesh filename="package://smb_description/urdf/new_payload/meshes/SMB_lidar_mount.dae"/>
      </geometry>
    </visual>
    <inertial>
      <origin rpy="0 0 0" xyz="0 0 0"/>
      <mass value="1e-4"/>
      <inertia ixx="3.3333333333333334e-13" ixy="0" ixz="0" iyy="3.3333333333333334e-13" iyz="0" izz="5e-13"/>
    </inertial>
  </link>
  <gazebo reference="lidar_mount_link">
    <material>Gazebo/Grey</material>
  </gazebo>
  <joint name="lidar_mount_joint" type="fixed">
    <origin rpy="0 0 0" xyz="0.00445 0 0.3265"/>
    <parent link="base_link"/>
    <child link="lidar_mount_link"/>
  </joint>
  <gazebo reference="lidar_mount_joint">
    <disableFixedJointLumping>true</disableFixedJointLumping>
  </gazebo>
  <link name="realsense_t265">
    <inertial>
      <mass value="0.001"/>
      <origin rpy="0 0 0" xyz="0 0 0"/>
      <inertia ixx="0.0001" ixy="0" ixz="0" iyy="0.000001" iyz="0" izz="0.0001"/>
    </inertial>
    <collision>
      <origin rpy="0 0 0" xyz="0 0 0"/>
      <geometry>
        <box size="0.013 0.108 0.025"/>
      </geometry>
    </collision>
    <visual>
      <origin rpy="0 0 0" xyz="0 0 0"/>
      <geometry>
        <box size="0.013 0.108 0.025"/>
      </geometry>
      <material name="black"/>
    </visual>
  </link>
  <gazebo reference="realsense_t265">
    <material>Gazebo/Black</material>
  </gazebo>
  <joint name="realsense_t265_joint" type="fixed">
    <parent link="imu_link"/>
    <child link="realsense_t265"/>
    <!-- <origin xyz="-${chassisLength/2.0+realsense_t265_width} 0.0 ${chassisHeight*0.5+realsense_t265_height*0.5}" rpy="0 0 ${PI}" /> -->
    <!-- Manually calibrated sensor orientation  -->
    <origin rpy="0 0 0" xyz="0.0537 0.0321 0.172"/>
  </joint>
  <joint name="camera_pose_frame_joint" type="fixed">
    <parent link="realsense_t265"/>
    <child link="camera_pose_frame"/>
    <origin rpy="0 0 0" xyz="0 0 0"/>
  </joint>
  <link name="camera_pose_frame"/>
  <link name="realsense_t265_odom_frame"/>
  <joint name="realsense_t265_odom_joint" type="fixed">
    <parent link="realsense_t265"/>
    <child link="realsense_t265_odom_frame"/>
    <origin rpy="1.5707963267948966 0 -1.5707963267948966" xyz="0 0.0091 0 "/>
  </joint>
  <link name="camera_imu_optical_frame"/>
  <joint name="realsense_t265_imu_joint" type="fixed">
    <parent link="realsense_t265_odom_frame"/>
    <child link="camera_imu_optical_frame"/>
    <origin rpy="0 3.141592653589793 0" xyz="0 0 0 "/>
  </joint>
  <gazebo>
    <plugin filename="libodometry_source_plugin.so" name="smb_odometry_plugin">
      <robotNamespace>smb</robotNamespace>
      <bodyName>realsense_t265</bodyName>
      <topicName>/camera/odom/sample</topicName>
      <odomFrame>camera_odom_frame</odomFrame>
      <childOdomFrame>camera_pose_frame</childOdomFrame>
      <publishTf>False</publishTf>
      <xyzOffset>0 0 0</xyzOffset>
      <rpyOffset>0 0 0</rpyOffset>
      <gaussianNoise>0</gaussianNoise>
      <updateRate>200</updateRate>
      <maxLinearSpeedBeforeSettle>0.01</maxLinearSpeedBeforeSettle>
      <maxAngularSpeedBeforeSettle>0.05</maxAngularSpeedBeforeSettle>
    </plugin>
  </gazebo>
  <gazebo reference="realsense_t265_joint">
    <disableFixedJointLumping>true</disableFixedJointLumping>
  </gazebo>
</robot>


